<?xml version="1.0" ?>


<robot name="mrm_nerfed" xmlns:xacro="http://ros.org/wiki/xacro">

	<xacro:macro name="mrm_nerfed" params="*origin parent:=base_link">
		
		<joint name="arm_base_joint" type="fixed">
			<xacro:insert_block name="origin" />
			<parent link="${parent}"/>
			<child link="arm_base_link"/>
		</joint>

		<!-- for Base -->

		<link name="arm_base_link">
			<inertial>
				<mass value = "0.286"/> <!-- kg -->
				<origin xyz = "0 0 0" rpy = "0 0 0"/>
			 	<inertia ixx="0.0001525" ixy="0.000000" ixz="0.000000"
						 iyx="0.000000" iyy="0.0001525" iyz="0.000000"
						 izx="0.000000" izy="0.000000" izz="0.000000" />
				</inertial>
			<collision>
				<origin xyz = "0 0 0" rpy = "0 0 0"/>
				<geometry>
					<box size="0.1 0.1 0.1"/>
				</geometry>
			</collision>
			<visual>
				<origin xyz = "0 0 0" rpy = "0 0 0"/> 
				<geometry>
					<mesh filename="package://mrm_nerfed/meshes/base0.5.STL" scale="0.001 0.001 0.001"/>
				</geometry>
			</visual>
		</link>

		<joint name="link_1_joint" type="revolute">
			<axis xyz="0 0 1"/>
			<limit effort="1000.0" lower="-2.61799" upper="2.61799" velocity="0.5"/>
			<origin xyz = "0 0 0.096751" rpy = "0 0 0"/> <!-- <origin xyz = "-0.005000 0 0.096751" rpy = "0 0 0"/> -->
			<parent link="arm_base_link"/>
			<child link="link_1"/>
		</joint>

	</xacro:macro>
</robot>